Ocorreu uma falha durante a sincronização de uma fonte externa.

Data/Hora: {{ data }}

Fonte Externa: {{ fonte_externa.nome }}
URL: {{ fonte_externa.url_sincronia }}
Tipo Fonte: {{ fonte_externa.tipo }}

Número de registros atual: {{ registros_atual|default:"0" }}

Mensagem de erro: {{ mensagem }}